Workbook

Sheet 1_MEDS_Baseline_Grid
A1: MPOB PALMNEX - MEDS ECONOMIC YIELD RESPONSE ENGINE (EXACT SYSTEM MATCH)
A3: PARAMETER INPUTS (SOIL, CLIMATE & ECONOMICS)
A5: Palm Age (Years) | B5: 12 | C5: years
A6: Planting Density (Palms/ha) | B6: 148 | C6: palms/ha
A7: Soil Drainage Class (1-5) | B7: 1 | C7: class (1=well drained)
A8: Soil Consistency Class (1-4) | B8: 1 | C8: class
A9: Slope Class (degrees) | B9: 0.5 | C9: deg
A10: Root Impedance Class | B10: 0.2 | C10: class
A11: Soil Organic Matter (%) | B11: 2 | C11: %
A12: Silt Content (%) | B12: 18 | C12: %
A13: Extractable K (cmol/kg) | B13: 0.13 | C13: cmol/kg
A14: Total Extractable Bases | B14: 1.3 | C14: cmol/kg
A15: Annual Rainfall (mm/year) | B15: 2000 | C15: mm/year
A16: FFB Price (RM/tonne) | B16: 800 | C16: RM/tonne
... A18: Muriate of Potash Cost (KCl) | B18: 1600 | C18: RM/tonne
A20: Calculated Baseline Yield Y0 (t/ha/yr): | B20: =ROUND(14.38 * ((9.823 - 5.221*B7 + 4.3*B11 + 50.04*(B13/B14)) / 18.206) * ((93.81 - 1.652*B5 - 0.1957*B6 - 9.101*B7 - 0.0116*B13) / 35.919892), 2) -> 14.38
A23: 1. MEDS FFB YIELD PREDICTION SURFACE Y(N,K) [t/ha/yr]
A25: N \ K (kg/palm) | B25: 0 | C25: 0.5 | D25: 1 | E25: 1.5 | F25: 2 | G25: 2.5 | H25: 3 | I25: 3.5 | J25: 4 | K25: 4.5 | L25: 5
A26: 0 | B26: =$B$20 + (0 / $B$16) -> 14.38 | C26: =$B$20 + (376 / $B$16) -> 14.85 | D26: =$B$20 + (680 / $B$16) -> 15.23 | E26: =$B$20 + (888 / $B$16) -> 15.49 | F26: =$B$20 + (1040 / $B$16) -> 15.68 | G26: =$B$20 + (1136 / $B$16) -> 15.8 | H26: =$B$20 + (1184 / $B$16) -> 15.86 | I26: =$B$20 + (1200 / $B$16) -> 15.88 | J26: =$B$20 + (1184 / $B$16) -> 15.86 | K26: =$B$20 + (1144 / $B$16) -> 15.81 | L26: =$B$20 + (1080 / $B$16) -> 15.73
A27: 0.5 | B27: =$B$20 + (672 / $B$16) -> 15.22 | C27: =$B$20 + (1104 / $B$16) -> 15.76 | D27: =$B$20 + (1472 / $B$16) -> 16.22 | E27: =$B$20 + (1728 / $B$16) -> 16.54 | F27: =$B$20 + (1936 / $B$16) -> 16.8 | G27: =$B$20 + (2080 / $B$16) -> 16.98 | H27: =$B$20 + (2184 / $B$16) -> 17.11 | I27: =$B$20 + (2240 / $B$16) -> 17.18 | J27: =$B$20 + (2264 / $B$16) -> 17.21 | K27: =$B$20 + (2264 / $B$16) -> 17.21 | L27: =$B$20 + (2240 / $B$16) -> 17.18
A28: 1 | B28: =$B$20 + (1216 / $B$16) -> 15.9 | C28: =$B$20 + (1712 / $B$16) -> 16.52 | D28: =$B$20 + (2136 / $B$16) -> 17.05 | E28: =$B$20 + (2448 / $B$16) -> 17.44 | F28: =$B$20 + (2720 / $B$16) -> 17.78 | G28: =$B$20 + (2904 / $B$16) -> 18.01 | H28: =$B$20 + (3056 / $B$16) -> 18.2 | I28: =$B$20 + (3160 / $B$16) -> 18.33 | J28: =$B$20 + (3232 / $B$16) -> 18.42 | K28: =$B$20 + (3272 / $B$16) -> 18.47 | L28: =$B$20 + (3288 / $B$16) -> 18.49
A29: 1.5 | B29: =$B$20 + (1552 / $B$16) -> 16.32 | C29: =$B$20 + (2088 / $B$16) -> 16.99 | D29: =$B$20 + (2568 / $B$16) -> 17.59 | E29: =$B$20 + (2928 / $B$16) -> 18.04 | F29: =$B$20 + (3240 / $B$16) -> 18.43 | G29: =$B$20 + (3472 / $B$16) -> 18.72 | H29: =$B$20 + (3664 / $B$16) -> 18.96 | I29: =$B$20 + (3808 / $B$16) -> 19.14 | J29: =$B$20 + (3912 / $B$16) -> 19.27 | K29: =$B$20 + (3984 / $B$16) -> 19.36 | L29: =$B$20 + (4032 / $B$16) -> 19.42
A30: 2 | B30: =$B$20 + (1800 / $B$16) -> 16.63 | C30: =$B$20 + (2392 / $B$16) -> 17.37 | D30: =$B$20 + (2920 / $B$16) -> 18.03 | E30: =$B$20 + (3328 / $B$16) -> 18.54 | F30: =$B$20 + (3688 / $B$16) -> 18.99 | G30: =$B$20 + (3960 / $B$16) -> 19.33 | H30: =$B$20 + (4200 / $B$16) -> 19.63 | I30: =$B$20 + (4376 / $B$16) -> 19.85 | J30: =$B$20 + (4528 / $B$16) -> 20.04 | K30: =$B$20 + (4632 / $B$16) -> 20.17 | L30: =$B$20 + (4712 / $B$16) -> 20.27
A31: 2.5 | B31: =$B$20 + (1944 / $B$16) -> 16.81 | C31: =$B$20 + (2576 / $B$16) -> 17.6 | D31: =$B$20 + (3144 / $B$16) -> 18.31 | E31: =$B$20 + (3592 / $B$16) -> 18.87 | F31: =$B$20 + (3992 / $B$16) -> 19.37 | G31: =$B$20 + (4296 / $B$16) -> 19.75 | H31: =$B$20 + (4568 / $B$16) -> 20.09 | I31: =$B$20 + (4776 / $B$16) -> 20.35 | J31: =$B$20 + (4952 / $B$16) -> 20.57 | K31: =$B$20 + (5088 / $B$16) -> 20.74 | L31: =$B$20 + (5200 / $B$16) -> 20.88
A32: 3 | B32: =$B$20 + (2032 / $B$16) -> 16.92 | C32: =$B$20 + (2704 / $B$16) -> 17.76 | D32: =$B$20 + (3320 / $B$16) -> 18.53 | E32: =$B$20 + (3808 / $B$16) -> 19.14 | F32: =$B$20 + (4240 / $B$16) -> 19.68 | G32: =$B$20 + (4584 / $B$16) -> 20.11 | H32: =$B$20 + (4896 / $B$16) -> 20.5 | I32: =$B$20 + (5136 / $B$16) -> 20.8 | J32: =$B$20 + (5344 / $B$16) -> 21.06 | K32: =$B$20 + (5504 / $B$16) -> 21.26 | L32: =$B$20 + (5648 / $B$16) -> 21.44
A33: 3.5 | B33: =$B$20 + (2064 / $B$16) -> 16.96 | C33: =$B$20 + (2776 / $B$16) -> 17.85 | D33: =$B$20 + (3424 / $B$16) -> 18.66 | E33: =$B$20 + (3944 / $B$16) -> 19.31 | F33: =$B$20 + (4408 / $B$16) -> 19.89 | G33: =$B$20 + (4784 / $B$16) -> 20.36 | H33: =$B$20 + (5120 / $B$16) -> 20.78 | I33: =$B$20 + (5384 / $B$16) -> 21.11 | J33: =$B$20 + (5624 / $B$16) -> 21.41 | K33: =$B$20 + (5808 / $B$16) -> 21.64 | L33: =$B$20 + (5968 / $B$16) -> 21.84
A34: 4 | B34: =$B$20 + (2072 / $B$16) -> 16.97 | C34: =$B$20 + (2816 / $B$16) -> 17.9 | D34: =$B$20 + (3504 / $B$16) -> 18.76 | E34: =$B$20 + (4048 / $B$16) -> 19.44 | F34: =$B$20 + (4552 / $B$16) -> 20.07 | G34: =$B$20 + (4952 / $B$16) -> 20.57 | H34: =$B$20 + (5320 / $B$16) -> 21.03 | I34: =$B$20 + (5608 / $B$16) -> 21.39 | J34: =$B$20 + (5872 / $B$16) -> 21.72 | K34: =$B$20 + (6080 / $B$16) -> 21.98 | L34: =$B$20 + (6264 / $B$16) -> 22.21
A35: 4.5 | B35: =$B$20 + (2056 / $B$16) -> 16.95 | C35: =$B$20 + (2832 / $B$16) -> 17.92 | D35: =$B$20 + (3544 / $B$16) -> 18.81 | E35: =$B$20 + (4120 / $B$16) -> 19.53 | F35: =$B$20 + (4640 / $B$16) -> 20.18 | G35: =$B$20 + (5064 / $B$16) -> 20.71 | H35: =$B$20 + (5456 / $B$16) -> 21.2 | I35: =$B$20 + (5768 / $B$16) -> 21.59 | J35: =$B$20 + (6048 / $B$16) -> 21.94 | K35: =$B$20 + (6272 / $B$16) -> 22.22 | L35: =$B$20 + (6480 / $B$16) -> 22.48
A36: 5 | B36: =$B$20 + (2024 / $B$16) -> 16.91 | C36: =$B$20 + (2824 / $B$16) -> 17.91 | D36: =$B$20 + (3568 / $B$16) -> 18.84 | E36: =$B$20 + (4168 / $B$16) -> 19.59 | F36: =$B$20 + (4720 / $B$16) -> 20.28 | G36: =$B$20 + (5160 / $B$16) -> 20.83 | H36: =$B$20 + (5576 / $B$16) -> 21.35 | I36: =$B$20 + (5904 / $B$16) -> 21.76 | J36: =$B$20 + (6208 / $B$16) -> 22.14 | K36: =$B$20 + (6456 / $B$16) -> 22.45 | L36: =$B$20 + (6680 / $B$16) -> 22.73
A37: 5.5 | B37: =$B$20 + (1984 / $B$16) -> 16.86 | C37: =$B$20 + (2808 / $B$16) -> 17.89 | D37: =$B$20 + (3568 / $B$16) -> 18.84 | E37: =$B$20 + (4192 / $B$16) -> 19.62 | F37: =$B$20 + (4760 / $B$16) -> 20.33 | G37: =$B$20 + (5224 / $B$16) -> 20.91 | H37: =$B$20 + (5656 / $B$16) -> 21.45 | I37: =$B$20 + (6008 / $B$16) -> 21.89 | J37: =$B$20 + (6328 / $B$16) -> 22.29 | K37: =$B$20 + (6584 / $B$16) -> 22.61 | L37: =$B$20 + (6824 / $B$16) -> 22.91
A38: 6 | B38: =$B$20 + (1936 / $B$16) -> 16.8 | C38: =$B$20 + (2776 / $B$16) -> 17.85 | D38: =$B$20 + (3568 / $B$16) -> 18.84 | E38: =$B$20 + (4208 / $B$16) -> 19.64 | F38: =$B$20 + (4800 / $B$16) -> 20.38 | G38: =$B$20 + (5280 / $B$16) -> 20.98 | H38: =$B$20 + (5728 / $B$16) -> 21.54 | I38: =$B$20 + (6096 / $B$16) -> 22 | J38: =$B$20 + (6432 / $B$16) -> 22.42 | K38: =$B$20 + (6704 / $B$16) -> 22.76 | L38: =$B$20 + (6960 / $B$16) -> 23.08
A41: 2. MEDS REVENUE GAIN SURFACE [RM/ha/yr]
A43: N \ K (kg/palm) | B43: 0 | C43: 0.5 | D43: 1 | E43: 1.5 | F43: 2 | G43: 2.5 | H43: 3 | I43: 3.5 | J43: 4 | K43: 4.5 | L43: 5
A44: 0 | B44: =ROUND((B26 - $B$20) * $B$16, 0) -> 0 | C44: =ROUND((C26 - $B$20) * $B$16, 0) -> 376 | D44: =ROUND((D26 - $B$20) * $B$16, 0) -> 680 | E44: =ROUND((E26 - $B$20) * $B$16, 0) -> 888 | F44: =ROUND((F26 - $B$20) * $B$16, 0) -> 1040 | G44: =ROUND((G26 - $B$20) * $B$16, 0) -> 1136 | H44: =ROUND((H26 - $B$20) * $B$16, 0) -> 1184 | I44: =ROUND((I26 - $B$20) * $B$16, 0) -> 1200 | ... L44: =ROUND((L26 - $B$20) * $B$16, 0) -> 1080
A45: 0.5 | B45: =ROUND((B27 - $B$20) * $B$16, 0) -> 672 | C45: =ROUND((C27 - $B$20) * $B$16, 0) -> 1104 | D45: =ROUND((D27 - $B$20) * $B$16, 0) -> 1472 | E45: =ROUND((E27 - $B$20) * $B$16, 0) -> 1728 | F45: =ROUND((F27 - $B$20) * $B$16, 0) -> 1936 | G45: =ROUND((G27 - $B$20) * $B$16, 0) -> 2080 | H45: =ROUND((H27 - $B$20) * $B$16, 0) -> 2184 | I45: =ROUND((I27 - $B$20) * $B$16, 0) -> 2240 | ... L45: =ROUND((L27 - $B$20) * $B$16, 0) -> 2240
A46: 1 | B46: =ROUND((B28 - $B$20) * $B$16, 0) -> 1216 | C46: =ROUND((C28 - $B$20) * $B$16, 0) -> 1712 | D46: =ROUND((D28 - $B$20) * $B$16, 0) -> 2136 | E46: =ROUND((E28 - $B$20) * $B$16, 0) -> 2448 | F46: =ROUND((F28 - $B$20) * $B$16, 0) -> 2720 | G46: =ROUND((G28 - $B$20) * $B$16, 0) -> 2904 | H46: =ROUND((H28 - $B$20) * $B$16, 0) -> 3056 | I46: =ROUND((I28 - $B$20) * $B$16, 0) -> 3160 | ... L46: =ROUND((L28 - $B$20) * $B$16, 0) -> 3288
A47: 1.5 | B47: =ROUND((B29 - $B$20) * $B$16, 0) -> 1552 | C47: =ROUND((C29 - $B$20) * $B$16, 0) -> 2088 | D47: =ROUND((D29 - $B$20) * $B$16, 0) -> 2568 | E47: =ROUND((E29 - $B$20) * $B$16, 0) -> 2928 | F47: =ROUND((F29 - $B$20) * $B$16, 0) -> 3240 | G47: =ROUND((G29 - $B$20) * $B$16, 0) -> 3472 | H47: =ROUND((H29 - $B$20) * $B$16, 0) -> 3664 | I47: =ROUND((I29 - $B$20) * $B$16, 0) -> 3808 | ... L47: =ROUND((L29 - $B$20) * $B$16, 0) -> 4032
A48: 2 | B48: =ROUND((B30 - $B$20) * $B$16, 0) -> 1800 | C48: =ROUND((C30 - $B$20) * $B$16, 0) -> 2392 | D48: =ROUND((D30 - $B$20) * $B$16, 0) -> 2920 | E48: =ROUND((E30 - $B$20) * $B$16, 0) -> 3328 | F48: =ROUND((F30 - $B$20) * $B$16, 0) -> 3688 | G48: =ROUND((G30 - $B$20) * $B$16, 0) -> 3960 | H48: =ROUND((H30 - $B$20) * $B$16, 0) -> 4200 | I48: =ROUND((I30 - $B$20) * $B$16, 0) -> 4376 | ... L48: =ROUND((L30 - $B$20) * $B$16, 0) -> 4712
A49: 2.5 | B49: =ROUND((B31 - $B$20) * $B$16, 0) -> 1944 | C49: =ROUND((C31 - $B$20) * $B$16, 0) -> 2576 | D49: =ROUND((D31 - $B$20) * $B$16, 0) -> 3144 | E49: =ROUND((E31 - $B$20) * $B$16, 0) -> 3592 | F49: =ROUND((F31 - $B$20) * $B$16, 0) -> 3992 | G49: =ROUND((G31 - $B$20) * $B$16, 0) -> 4296 | H49: =ROUND((H31 - $B$20) * $B$16, 0) -> 4568 | I49: =ROUND((I31 - $B$20) * $B$16, 0) -> 4776 | ... L49: =ROUND((L31 - $B$20) * $B$16, 0) -> 5200
A50: 3 | B50: =ROUND((B32 - $B$20) * $B$16, 0) -> 2032 | C50: =ROUND((C32 - $B$20) * $B$16, 0) -> 2704 | D50: =ROUND((D32 - $B$20) * $B$16, 0) -> 3320 | E50: =ROUND((E32 - $B$20) * $B$16, 0) -> 3808 | F50: =ROUND((F32 - $B$20) * $B$16, 0) -> 4240 | G50: =ROUND((G32 - $B$20) * $B$16, 0) -> 4584 | H50: =ROUND((H32 - $B$20) * $B$16, 0) -> 4896 | I50: =ROUND((I32 - $B$20) * $B$16, 0) -> 5136 | ... L50: =ROUND((L32 - $B$20) * $B$16, 0) -> 5648
...

Sheet 2_MPOB_Foster_Nutrient_Balance
B2: GRADING NUTRIENT DEFICIENCIES (K and Mg) | L2: MEAN OPTIMUM LEAF NUTRIENT LEVELS AND RATIOS | U2: FERTILIZER ADJUSTMENT
L3: STANDARD
A4: A | B4: Total Leaf Cation (TLC) | C4: = | D4: Leaf K | E4: + | F4: Leaf Mg | G4: + | H4: Leaf Ca | I4: x | J4: 1000 | L4: Leaf Nutrients | M4: Inland Soils | N4: Coastal Soils | P4: Leaf Nutrients | Q4: Inland Soils | R4: Coastal Soils | U4: Nutrient Deficiency rating | V4: Potential Yield Response (t/ha/yr) | W4: Fertilizer Adjustment (kg/palm/yr)
B5: cmol/kg dry matter | D5: 39.1/1 | F5: 24.3/2 | H5: 40.1/2 | L5: N | M5: 2.763 | N5: 2.603 | P5: N | Q5: 2.128 | R5: 2.6 | S5: input | U5: Excessive | V5: 0 | W5: - 0.5 to -1
L6: P/N | M6: 0.06081 | N6: 0.06227 | P6: P/N | Q6: =Q11/Q5 -> 0.068139098 | R6: =R11/R5 -> 0.062307692 | U6: Satisfactory | V6: 0 to 1 | W6: 0
D7: Leaf K | E7: + | F7: Leaf Mg | G7: + | H7: Leaf Ca | I7: x | J7: 1000 | L7: N/K | M7: 2.594 | N7: 2.927 | P7: N/K | Q7: =Q5/Q17 -> 2.2376446 | R7: =R5/R17 -> 2.8792913 | U7: Low | V7: 1 to 2 | W7: 0 to 1
D8: 39.1 | F8: 12.15 | H8: 20.05 | L8: Mg/N | M8: 0.09759 | N8: 0.1106 | P8: Mg/N | Q8: =Q23/Q5 -> 0.23496241 | R8: =R23/R5 -> 0.11061538 | U8: Deficient | V8: 2 to 3 | W8: 0 to 2
L9: TB/N | M9: 31.4 | N9: 27.55 | P9: TLC/N | Q9: =Q29/Q5 -> 38.035023 | R9: =R29/R5 -> 0 | U9: Very Deficient | V9: > 3 | W9: 0 to 3
B10: Deficiency rating of Leaf K and Mg | F10: X/TLC | G10: Deficiency rating
D11: B | F11: <25 | G11: Deficient | L11: P | M11: 0.1678 | N11: 0.162 | P11: P | Q11: 0.145 | R11: 0.162 | S11: input | U11: Note:
F12: 25 - 30 | G12: Low | L12: P/N | M12: 0.06081 | N12: 0.6227 | P12: P/N | Q12: =Q11/Q5 -> 0.068139098 | R12: =R11/R5 -> 0.062307692 | U12: SH increase fertilizer rate only if nutrient is classified as deficient
F13: > 30 | G13: Sufficient | L13: P/K | M13: 0.1575 | N13: 0.1818 | P13: P/K | Q13: =Q11/Q17 -> 0.15247108 | R13: =R11/R17 -> 0.17940199 | U13: Larga plantation, increase fertilizer when average over a number of fields are classified as low
L14: P/Mg | M14: 0.6462 | N14: 0.5865 | P14: P/Mg | Q14: =Q11/Q23 -> 0.29 | R14: =R11/R23 -> 0.56328234
L15: TB/P | M15: 516.5 | N15: 443.8 | P15: TLC/P | Q15: =Q29/Q11 -> 558.19675 | R15: =R29/R11 -> 0 | U15: AUTOMATIC SATELLITE LEAF DIAGNOSIS & FERTILIZER ADJUSTMENT CALCULATOR
B16: DATA | D16: INPUT | U16: (INLAND) - for example
B17: Leaf K | C17: = | D17: 0.951 | L17: K | M17: 1.087 | N17: 0.903 | P17: K | Q17: 0.951 | R17: 0.903 | S17: input | U17: Element | V17: Satellite Leaf % | W17: Inland Optimum Target % | X17: Ratio (Sat/Target) | Y17: Nutrient Deficiency Rating | Z17: Fertilizer Adjustment (kg/palm/yr)
B18: Leaf Mg | C18: = | D18: 0.274 | L18: N/K | M18: 2.594 | N18: 2.927 | P18: N/K | Q18: =Q5/Q17 -> 2.2376446 | R18: =R5/R17 -> 2.8792913 | U18: Nitrogen (N) | V18: =Q5 -> 2.128 | W18: =M5 -> 2.763 | X18: =V18/W18 -> 0.77017734 | Y18: =IF(X18>=1.05,"Excessive", IF(X18>=0.92,"Satisfactory / Optimum", IF(X18>=0.8,"Low / Mild Deficit", IF(X18>=0.65,"Deficient","Very Deficient")))) -> Deficient | Z18: =IF(X18>=1.05, -0.5, IF(X18>=0.92, 0, IF(X18>=0.8, 0.5, IF(X18>=0.65, 1.5, 2.5)))) -> 1.5 | AA18: =W8 -> 0 to 2
B19: Leaf Ca | C19: = | D19: 0.683 | L19: P/K | M19: 0.1575 | N19: 0.1818 | P19: P/K | Q19: =Q11/Q17 -> 0.15247108 | R19: =R11/R17 -> 0.17940199 | U19: Phosphorus (P) | V19: =Q11 -> 0.145 | W19: =M11 -> 0.1678 | X19: =V19/W19 -> 0.86412396 | Y19: =IF(X19>=1.05,"Excessive", IF(X19>=0.92,"Satisfactory / Optimum", IF(X19>=0.8,"Low / Mild Deficit", IF(X19>=0.65,"Deficient","Very Deficient")))) -> Low / Mild Deficit | Z19: =IF(X19>=1.05, -0.5, IF(X19>=0.92, 0, IF(X19>=0.8, 0.5, IF(X19>=0.65, 1.5, 2.5)))) -> 0.5 | AA19: =W7 -> 0 to 1
L20: K/Mg | M20: 4.215 | N20: 3.323 | P20: K/Mg | Q20: =Q17/Q23 -> 1.902 | R20: =R17/R23 -> 3.1397775 | U20: Potassium (K) | V20: =Q17 -> 0.951 | W20: =M17 -> 1.087 | X20: =V20/W20 -> 0.874885 | Y20: =IF(X20>=1.05,"Excessive", IF(X20>=0.92,"Satisfactory / Optimum", IF(X20>=0.8,"Low / Mild Deficit", IF(X20>=0.65,"Deficient","Very Deficient")))) -> Low / Mild Deficit | Z20: =IF(X20>=1.05, -0.5, IF(X20>=0.92, 0, IF(X20>=0.8, 0.5, IF(X20>=0.65, 1.5, 2.5)))) -> 0.5 | AA20: =W7 -> 0 to 1
B21: CALCULATED | L21: TB/K | M21: 81.01 | N21: 80.67 | P21: TLC/K | Q21: =Q29/Q17 -> 85.108863 | R21: =R29/R17 -> 0 | U21: Magnesium (Mg) | V21: =Q23 -> 0.5 | W21: =M23 -> 0.269 | X21: =V21/W21 -> 1.8587361 | Y21: =IF(X21>=1.05,"Excessive", IF(X21>=0.92,"Satisfactory / Optimum", IF(X21>=0.8,"Low / Mild Deficit", IF(X21>=0.65,"Deficient","Very Deficient")))) -> Excessive | Z21: =IF(X21>=1.05, -0.5, IF(X21>=0.92, 0, IF(X21>=0.8, 0.5, IF(X21>=0.65, 1.5, 2.5)))) -> -0.5 | AA21: =W5 -> - 0.5 to -1
B22: TLC | D22: =(D17/39.1+D18/12.15+D19/20.05)*1000 -> 80.938529 | F22: A
L23: Mg | M23: 0.269 | N23: 0.2876 | P23: Mg | Q23: 0.5 | R23: 0.2876 | S23: input | W23: This value is from the LEFT side table. | X23: Ratio = X / Target | Y23: This indicator is from TOP table.
B24: DEFICIENCY RATING | D24: X/TLC | F24: B | L24: Mg/N | M24: 0.09759 | N24: 0.1106 | P24: Mg/N | Q24: =Q23/Q5 -> 0.23496241 | R24: =R23/R5 -> 0.11061538
B25: K/TLC | D25: =(D17/39.1)*1000 -> 24.322251 | H25: =IF(D25>30, "Sufficient", IF(D25>=25, "Low", "Deficient")) -> Deficient | L25: P/Mg | M25: 0.6462 | N25: 0.5865 | P25: P/Mg | Q25: =Q11/Q5 -> 0.068139098 | R25: =R11/R5 -> 0.062307692
B26: Mg/TLC | D26: =(D18/12.15)*1000 -> 22.55144 | H26: =IF(D26>30, "Sufficient", IF(D26>=25, "Low", "Deficient")) -> Deficient | L26: K/Mg | M26: 4.215 | N26: 3.323 | P26: K/Mg | Q26: =Q17/Q23 -> 1.902 | R26: =R17/R23 -> 3.1397775 | X26: This equation from LEFT
B27: Ca/TLC | D27: =(D19/20.05)*1000 -> 34.064838 | H27: =IF(D27>30, "Sufficient", IF(D27>=25, "Low", "Deficient")) -> Sufficient | L27: TB/Mg | M27: 331.6 | N27: 257.5 | P27: TLC/Mg | Q27: =Q29/Q23 -> 161.87706 | R27: =R29/R23 -> 0
O29: A | P29: TLC | Q29: =D22 -> 80.938529 | S29: input

Sheet 3_Final_Fertilizer_Rec
A1: INTEGRATED RECOMMENDATION SUMMARY TABLE (MEDS BASELINE + SATELLITE DEFICIT ADJUSTMENT)
A3: Soil Analysis | C3: We chose this in OPENS
A5: Element | B5: Satellite Leaf (%) | C5: MEDS Baseline Rate (kg/palm) | D5: MPOB Foster Optimum Benchmarks in Sheet 2 (%) | E5: Satellite Adj (kg/palm) | F5: Final Rec (kg/palm) | G5: Final Rec (kg/ha) | H5: Recommended Commercial Product | I5: Product Rate (kg/palm)
A6: Nitrogen (N) | B6: 2.128 | C6: ='1_MEDS_Baseline_Grid'!A36 -> 5 | E6: =ROUND(C6 * (('2_MPOB_Foster_Nutrient_Balance'!M5 - B6) / '2_MPOB_Foster_Nutrient_Balance'!M5), 2) -> 1.15 | F6: =C6+E6 -> 6.15 | G6: =F6*'1_MEDS_Baseline_Grid'!$B$6 -> 910.2 | H6: Ammonium Sulphate (SA - 21% N) | I6: =F6/0.21 -> 29.285714
A7: Phosphorus (P) | B7: 0.145 | C7: 0.27 | D7: ='2_MPOB_Foster_Nutrient_Balance'!M11 -> 0.1678 | E7: ='2_MPOB_Foster_Nutrient_Balance'!Z19 -> 0.5 | F7: =MAX(0, C7 + E7) -> 0.77 | G7: =F7*'1_MEDS_Baseline_Grid'!$B$6 -> 113.96 | H7: Rock Phosphate (CIRP - 13% P) | I7: =F7/0.13 -> 5.9230769
A8: Potassium (K) | B8: 0.951 | C8: ='1_MEDS_Baseline_Grid'!K25 -> 4.5 | E8: =ROUND(C8 * (('2_MPOB_Foster_Nutrient_Balance'!M17 - B8) / '2_MPOB_Foster_Nutrient_Balance'!M17), 2) -> 0.56 | F8: =C8+E8 -> 5.06 | G8: =F8*'1_MEDS_Baseline_Grid'!$B$6 -> 748.88 | H8: Muriate of Potash (MOP - 50% K) | I8: =F8/0.5 -> 10.12
A9: Magnesium (Mg) | B9: 0.5 | C9: 0 | D9: ='2_MPOB_Foster_Nutrient_Balance'!M23 -> 0.269 | E9: ='2_MPOB_Foster_Nutrient_Balance'!Z21 -> -0.5 | F9: =MAX(0, C9 + E9) -> 0 | G9: =F9*'1_MEDS_Baseline_Grid'!$B$6 -> 0 | H9: Kieserite (16% Mg) | I9: =F9/0.16 -> 0
A12: EXACT AGRONOMIC STRUCTURE & LINKING EXPLANATION:
A14: 1. Nitrogen (N) & Potassium (K): | B14: Baseline rates come EXCLUSIVELY from the MEDS Engine ('1_MEDS_Baseline_Grid'). Deficits are adjusted from Satellite Leaf % readings against target thresholds.
A15: 2. Phosphorus (P) & Magnesium (Mg): | B15: Baseline rates come EXCLUSIVELY from MPOB Foster Guidelines ('2_MPOB_Foster_Nutrient_Balance'). MEDS does not calculate P and Mg baseline, so the MEDS Baseline Rate cell is intentionally blank/grayed out.
A16: 3. Satellite Deficit Adjustment (kg/palm): | B16: Calculated automatically from Satellite Leaf % vs. Target Leaf % using MPOB Foster deficiency ratings.
A17: 4. Final Recommendation (kg/palm): | B17: N & K = MEDS Baseline + Satellite Adj | P & Mg = MPOB Baseline + Satellite Adj.
A18: 5. Final Recommendation (kg/ha):

Sheet 4_Current_Usage_Analysis
A1: MPOB PALMNEX - CURRENT FERTILIZER USAGE & VARIANCE ANALYSIS (METHOD 1 & METHOD 2)
A3: 1. CURRENT ESTATE FERTILIZER USAGE INPUTS
C4: Oxide Conversion to Pure Element
A5: Current Compound Fertilizer Grade | B5: NPK 17/17/17/3 | C5: Grade Specs
A6: Compound Nitrogen Content (N %) | B6: 0.17 | C6: % N
A7: Compound Phosphate Content (P2O5 %) | B7: 0.17 | C7: % P2O5 (7.42% P)
A8: Compound Potash Content (K2O %) | B8: 0.17 | C8: % K2O (14.11% K)
A9: Compound Magnesium Content (MgO %) | B9: 0.03 | C9: % MgO (1.81% Mg)
A10: Current Application Rate (kg/ha/year) | B10: 680 | C10: kg/ha/yr
A11: Current Compound Price (RM/tonne) | B11: 2200 | C11: RM/tonne
A12: Planting Density (palms/ha) | B12: ='1_MEDS_Baseline_Grid'!B6 -> 148 | C12: palms/ha
A14: 2. METHOD 1: NET TOP-UP & GAP ANALYSIS (TARGET REC vs CURRENT APPLIED)
G15: Straight Fertilizer Recommendations
A16: Element | B16: Target Rec Rate (kg/palm) | C16: Current Applied Rate (kg/palm) | D16: Current Applied Rate (kg/ha) | E16: Net Top-Up Needed (kg/palm) | F16: Net Top-Up Needed (kg/ha) | G16: Recommended Straight Top-Up Product | H16: Additional Product Needed (kg/palm) | I16: Additional Product Needed (kg/ha)
A17: Nitrogen (N) | B17: ='3_Final_Fertilizer_Rec'!E6 -> 1.15 | C17: =ROUND(($B$10*$B$6)/$B$12, 3) -> 0.781 | D17: =ROUND($B$10*$B$6, 2) -> 115.6 | E17: =MAX(0, B17-C17) -> 0.369 | F17: =E17*$B$12 -> 54.612 | G17: Ammonium Sulphate (SA - 21% N) | H17: =E17/0.21 -> 1.7571429 | I17: =H17*$B$12 -> 260.05714
A18: Phosphorus (P) | B18: ='3_Final_Fertilizer_Rec'!E7 -> 0.5 | C18: =ROUND(($B$10*($B$7*0.4364))/$B$12, 3) -> 0.341 | D18: =ROUND($B$10*($B$7*0.4364), 2) -> 50.45 | E18: =MAX(0, B18-C18) -> 0.159 | F18: =E18*$B$12 -> 23.532 | G18: Rock Phosphate (CIRP - 13% P) | H18: =E18/0.13 -> 1.2230769 | I18: =H18*$B$12 -> 181.01538
A19: Potassium (K) | B19: ='3_Final_Fertilizer_Rec'!E8 -> 0.56 | C19: =ROUND(($B$10*($B$8*0.8302))/$B$12, 3) -> 0.648 | D19: =ROUND($B$10*($B$8*0.8302), 2) -> 95.97 | E19: =MAX(0, B19-C19) -> 0 | F19: =E19*$B$12 -> 0 | G19: Muriate of Potash (MOP - 50% K) | H19: =E19/0.5 -> 0 | I19: =H19*$B$12 -> 0
A20: Magnesium (Mg) | B20: ='3_Final_Fertilizer_Rec'!E9 -> -0.5 | C20: =ROUND(($B$10*($B$9*0.603))/$B$12, 3) -> 0.083 | D20: =ROUND($B$10*($B$9*0.603), 2) -> 12.3 | E20: =MAX(0, B20-C20) -> 0 | F20: =E20*$B$12 -> 0 | G20: Kieserite (16% Mg) | H20: =E20/0.16 -> 0 | I20: =H20*$B$12 -> 0
A23: 3. METHOD 2: ESTATE FINANCIAL SPEND & NET REVENUE VARIANCE ANALYSIS
A25: Financial Metric | B25: Current Estate Regime (680 kg/ha NPK 17/17/17/3) | C25: Target Recommended Regime (Straight Fertilizers) | D25: Financial Variance (Gain / Savings) | E25: Calculation Rationale & Formula
A26: Annual Fertilizer Cost (RM/ha/yr) | B26: =ROUND(($B$10/1000)*$B$11, 2) -> 1496 | C26: =ROUND(('3_Final_Fertilizer_Rec'!H6*B12/1000*'1_MEDS_Baseline_Grid'!B17) + ('3_Final_Fertilizer_Rec'!H7*B12/1000*1100) + ('3_Final_Fertilizer_Rec'!H8*B12/1000*'1_MEDS_Baseline_Grid'!B18) + ('3_Final_Fertilizer_Rec'!H9*B12/1000*900), 2) -> #VALUE! | D26: =C26-B26 -> #VALUE! | E26: Calculates total annual fertilizer expenditure per hectare.
A27: Predicted FFB Yield (t/ha/yr) | B27: ='1_MEDS_Baseline_Grid'!B20 -> 14.38 | C27: ='3_Final_Fertilizer_Rec'!F6/'1_MEDS_Baseline_Grid'!B6 + '1_MEDS_Baseline_Grid'!B20 -> 14.421554 | D27: =C27-B27 -> 0.041554054 | E27: Predicts annual FFB harvest tonnes per hectare.
A28: Gross FFB Revenue (RM/ha/yr) | B28: =ROUND(B27*'1_MEDS_Baseline_Grid'!B16, 2) -> 11504 | C28: =ROUND(C27*'1_MEDS_Baseline_Grid'!B16, 2) -> 11537.24 | D28: =C28-B28 -> 33.24 | E28: Gross sales revenue = FFB Yield x FFB Price (RM 800/t).
A29: NET ANNUAL PROFIT (RM/ha/yr) | B29: =ROUND(B28-B26, 2) -> 10008 | C29: =ROUND(C28-C26, 2) -> #VALUE! | D29: =C29-B29 -> #VALUE! | E29: NET PROFIT GAIN = Gross Revenue Gain minus Fertilizer Cost Variance.
